<?xml version="1.0" ?>
<!-- =================================================================================== -->
<!-- |    This document was autogenerated by xacro from snake.xacro                    | -->
<!-- |    EDITING THIS FILE BY HAND IS NOT RECOMMENDED                                 | -->
<!-- =================================================================================== -->
<robot name="snake">
  <material name="blue">
    <color rgba="0 0 0.8 0.7"/>
  </material>
  <material name="green">
    <color rgba="0 0.8 0 0.7"/>
  </material>
  <!-- Base -->
  <link name="base">
    <visual>
      <origin rpy="0 0 0" xyz="0 0 0"/>
      <geometry>
        <box size="0.001 0.00 0.001"/>
      </geometry>
      <material name="White">
        <color rgba="1.0 1.0 1.0 1.0"/>
      </material>
    </visual>
    <collision>
      <origin rpy="0 0 0" xyz="0 0 0"/>
      <geometry>
        <box size="0.001 0.00 0.001"/>
      </geometry>
    </collision>
  </link>
  <joint name="base_to_group_1_link0" type="fixed">
    <parent link="base"/>
    <child link="group_1_link0"/>
    <origin rpy="0 0 0" xyz="0 0 0"/>
  </joint>
  <link name="group_1_link0">
    <visual>
      <geometry>
        <cylinder length="0.04" radius="0.04"/>
      </geometry>
      <origin rpy="0 0 0" xyz="0 0 0.02"/>
      <material name="green"/>
    </visual>
    <collision>
      <geometry>
        <cylinder length="0.04" radius="0.04"/>
      </geometry>
      <origin rpy="0 0 0" xyz="0 0 0.02"/>
    </collision>
  </link>
  <joint name="group_1_link0_to_group_1_link1" type="revolute">
    <parent link="group_1_link0"/>
    <child link="group_1_link1"/>
    <origin rpy="0 0 0" xyz="0 0 0.04"/>
    <axis xyz="1 0 0"/>
    <limit effort="100" lower="-1.5707963267948966" upper="1.5707963267948966" velocity="5"/>
  </joint>
  <link name="group_1_link1">
    <visual>
      <geometry>
        <cylinder length="0.092" radius="0.02"/>
      </geometry>
      <origin rpy="0 0 0" xyz="0 0 0.046"/>
      <material name="blue"/>
    </visual>
    <collision>
      <geometry>
        <cylinder length="0.092" radius="0.02"/>
      </geometry>
      <origin rpy="0 0 0" xyz="0 0 0.046"/>
    </collision>
  </link>
  <joint name="group_1_link1_to_group_1_link2" type="revolute">
    <parent link="group_1_link1"/>
    <child link="group_1_link2"/>
    <origin rpy="0 0 0" xyz="0 0 0.092"/>
    <axis xyz="0 0 1"/>
    <limit effort="100" lower="-1.0471975511965976" upper="1.5707963267948966" velocity="5"/>
  </joint>
  <link name="group_1_link2">
    <visual>
      <geometry>
        <box size="0.04 0.04 0.07"/>
      </geometry>
      <origin rpy="0 0 0" xyz="0 0 0.035"/>
      <material name="blue"/>
    </visual>
    <collision>
      <geometry>
        <box size="0.04 0.04 0.07"/>
      </geometry>
      <origin rpy="0 0 0" xyz="0 0 0.035"/>
    </collision>
  </link>
  <joint name="group_1_link2_to_group_1_link3" type="revolute">
    <parent link="group_1_link2"/>
    <child link="group_1_link3"/>
    <origin rpy="0 0 0" xyz="0 0 0.07"/>
    <axis xyz="0 1 0"/>
    <limit effort="100" lower="-1.0471975511965976" upper="1.0471975511965976" velocity="5"/>
  </joint>
  <link name="group_1_link3">
    <visual>
      <geometry>
        <cylinder length="0.04" radius="0.02"/>
      </geometry>
      <origin rpy="0 0 0" xyz="0 0 0.02"/>
      <material name="blue"/>
    </visual>
    <collision>
      <geometry>
        <cylinder length="0.04" radius="0.02"/>
      </geometry>
      <origin rpy="0 0 0" xyz="0 0 0.02"/>
    </collision>
  </link>
  <joint name="group_1_link3_to_group_2_link1" type="revolute">
    <parent link="group_1_link3"/>
    <child link="group_2_link1"/>
    <origin rpy="0 0 0" xyz="0 0 0.04"/>
    <axis xyz="1 0 0"/>
    <limit effort="100" lower="-1.5707963267948966" upper="1.5707963267948966" velocity="5"/>
  </joint>
  <link name="group_2_link1">
    <visual>
      <geometry>
        <cylinder length="0.092" radius="0.02"/>
      </geometry>
      <origin rpy="0 0 0" xyz="0 0 0.046"/>
      <material name="blue"/>
    </visual>
    <collision>
      <geometry>
        <cylinder length="0.092" radius="0.02"/>
      </geometry>
      <origin rpy="0 0 0" xyz="0 0 0.046"/>
    </collision>
  </link>
  <joint name="group_2_link1_to_group_2_link2" type="revolute">
    <parent link="group_2_link1"/>
    <child link="group_2_link2"/>
    <origin rpy="0 0 0" xyz="0 0 0.092"/>
    <axis xyz="0 0 1"/>
    <limit effort="100" lower="-1.0471975511965976" upper="1.5707963267948966" velocity="5"/>
  </joint>
  <link name="group_2_link2">
    <visual>
      <geometry>
        <box size="0.04 0.04 0.07"/>
      </geometry>
      <origin rpy="0 0 0" xyz="0 0 0.035"/>
      <material name="blue"/>
    </visual>
    <collision>
      <geometry>
        <box size="0.04 0.04 0.07"/>
      </geometry>
      <origin rpy="0 0 0" xyz="0 0 0.035"/>
    </collision>
  </link>
  <joint name="group_2_link2_to_group_2_link3" type="revolute">
    <parent link="group_2_link2"/>
    <child link="group_2_link3"/>
    <origin rpy="0 0 0" xyz="0 0 0.07"/>
    <axis xyz="0 1 0"/>
    <limit effort="100" lower="-1.0471975511965976" upper="1.0471975511965976" velocity="5"/>
  </joint>
  <link name="group_2_link3">
    <visual>
      <geometry>
        <cylinder length="0.04" radius="0.02"/>
      </geometry>
      <origin rpy="0 0 0" xyz="0 0 0.02"/>
      <material name="blue"/>
    </visual>
    <collision>
      <geometry>
        <cylinder length="0.04" radius="0.02"/>
      </geometry>
      <origin rpy="0 0 0" xyz="0 0 0.02"/>
    </collision>
  </link>
  <joint name="group_2_link3_to_group_3_link1" type="revolute">
    <parent link="group_2_link3"/>
    <child link="group_3_link1"/>
    <origin rpy="0 0 0" xyz="0 0 0.04"/>
    <axis xyz="1 0 0"/>
    <limit effort="100" lower="-1.5707963267948966" upper="1.5707963267948966" velocity="5"/>
  </joint>
  <link name="group_3_link1">
    <visual>
      <geometry>
        <cylinder length="0.092" radius="0.02"/>
      </geometry>
      <origin rpy="0 0 0" xyz="0 0 0.046"/>
      <material name="blue"/>
    </visual>
    <collision>
      <geometry>
        <cylinder length="0.092" radius="0.02"/>
      </geometry>
      <origin rpy="0 0 0" xyz="0 0 0.046"/>
    </collision>
  </link>
  <joint name="group_3_link1_to_group_3_link2" type="revolute">
    <parent link="group_3_link1"/>
    <child link="group_3_link2"/>
    <origin rpy="0 0 0" xyz="0 0 0.092"/>
    <axis xyz="0 0 1"/>
    <limit effort="100" lower="-1.0471975511965976" upper="1.5707963267948966" velocity="5"/>
  </joint>
  <link name="group_3_link2">
    <visual>
      <geometry>
        <box size="0.04 0.04 0.07"/>
      </geometry>
      <origin rpy="0 0 0" xyz="0 0 0.035"/>
      <material name="blue"/>
    </visual>
    <collision>
      <geometry>
        <box size="0.04 0.04 0.07"/>
      </geometry>
      <origin rpy="0 0 0" xyz="0 0 0.035"/>
    </collision>
  </link>
  <joint name="group_3_link2_to_group_3_link3" type="revolute">
    <parent link="group_3_link2"/>
    <child link="group_3_link3"/>
    <origin rpy="0 0 0" xyz="0 0 0.07"/>
    <axis xyz="0 1 0"/>
    <limit effort="100" lower="-1.0471975511965976" upper="1.0471975511965976" velocity="5"/>
  </joint>
  <link name="group_3_link3">
    <visual>
      <geometry>
        <cylinder length="0.04" radius="0.02"/>
      </geometry>
      <origin rpy="0 0 0" xyz="0 0 0.02"/>
      <material name="blue"/>
    </visual>
    <collision>
      <geometry>
        <cylinder length="0.04" radius="0.02"/>
      </geometry>
      <origin rpy="0 0 0" xyz="0 0 0.02"/>
    </collision>
  </link>
  <joint name="group_3_link3_to_group_4_link1" type="revolute">
    <parent link="group_3_link3"/>
    <child link="group_4_link1"/>
    <origin rpy="0 0 0" xyz="0 0 0.04"/>
    <axis xyz="1 0 0"/>
    <limit effort="100" lower="-1.5707963267948966" upper="1.5707963267948966" velocity="5"/>
  </joint>
  <link name="group_4_link1">
    <visual>
      <geometry>
        <cylinder length="0.092" radius="0.02"/>
      </geometry>
      <origin rpy="0 0 0" xyz="0 0 0.046"/>
      <material name="blue"/>
    </visual>
    <collision>
      <geometry>
        <cylinder length="0.092" radius="0.02"/>
      </geometry>
      <origin rpy="0 0 0" xyz="0 0 0.046"/>
    </collision>
  </link>
  <joint name="group_4_link1_to_group_4_link2" type="revolute">
    <parent link="group_4_link1"/>
    <child link="group_4_link2"/>
    <origin rpy="0 0 0" xyz="0 0 0.092"/>
    <axis xyz="0 0 1"/>
    <limit effort="100" lower="-1.0471975511965976" upper="1.5707963267948966" velocity="5"/>
  </joint>
  <link name="group_4_link2">
    <visual>
      <geometry>
        <box size="0.04 0.04 0.07"/>
      </geometry>
      <origin rpy="0 0 0" xyz="0 0 0.035"/>
      <material name="blue"/>
    </visual>
    <collision>
      <geometry>
        <box size="0.04 0.04 0.07"/>
      </geometry>
      <origin rpy="0 0 0" xyz="0 0 0.035"/>
    </collision>
  </link>
  <joint name="group_4_link2_to_group_4_link3" type="revolute">
    <parent link="group_4_link2"/>
    <child link="group_4_link3"/>
    <origin rpy="0 0 0" xyz="0 0 0.07"/>
    <axis xyz="0 1 0"/>
    <limit effort="100" lower="-1.0471975511965976" upper="1.0471975511965976" velocity="5"/>
  </joint>
  <link name="group_4_link3">
    <visual>
      <geometry>
        <cylinder length="0.04" radius="0.02"/>
      </geometry>
      <origin rpy="0 0 0" xyz="0 0 0.02"/>
      <material name="blue"/>
    </visual>
    <collision>
      <geometry>
        <cylinder length="0.04" radius="0.02"/>
      </geometry>
      <origin rpy="0 0 0" xyz="0 0 0.02"/>
    </collision>
  </link>
  <joint name="group_4_link3_to_group_5_link1" type="revolute">
    <parent link="group_4_link3"/>
    <child link="group_5_link1"/>
    <origin rpy="0 0 0" xyz="0 0 0.04"/>
    <axis xyz="1 0 0"/>
    <limit effort="100" lower="-1.5707963267948966" upper="1.5707963267948966" velocity="5"/>
  </joint>
  <link name="group_5_link1">
    <visual>
      <geometry>
        <cylinder length="0.092" radius="0.02"/>
      </geometry>
      <origin rpy="0 0 0" xyz="0 0 0.046"/>
      <material name="blue"/>
    </visual>
    <collision>
      <geometry>
        <cylinder length="0.092" radius="0.02"/>
      </geometry>
      <origin rpy="0 0 0" xyz="0 0 0.046"/>
    </collision>
  </link>
  <joint name="group_5_link1_to_group_5_link2" type="revolute">
    <parent link="group_5_link1"/>
    <child link="group_5_link2"/>
    <origin rpy="0 0 0" xyz="0 0 0.092"/>
    <axis xyz="0 0 1"/>
    <limit effort="100" lower="-1.0471975511965976" upper="1.5707963267948966" velocity="5"/>
  </joint>
  <link name="group_5_link2">
    <visual>
      <geometry>
        <box size="0.04 0.04 0.07"/>
      </geometry>
      <origin rpy="0 0 0" xyz="0 0 0.035"/>
      <material name="blue"/>
    </visual>
    <collision>
      <geometry>
        <box size="0.04 0.04 0.07"/>
      </geometry>
      <origin rpy="0 0 0" xyz="0 0 0.035"/>
    </collision>
  </link>
  <joint name="group_5_link2_to_group_5_link3" type="revolute">
    <parent link="group_5_link2"/>
    <child link="group_5_link3"/>
    <origin rpy="0 0 0" xyz="0 0 0.07"/>
    <axis xyz="0 1 0"/>
    <limit effort="100" lower="-1.0471975511965976" upper="1.0471975511965976" velocity="5"/>
  </joint>
  <link name="group_5_link3">
    <visual>
      <geometry>
        <cylinder length="0.04" radius="0.02"/>
      </geometry>
      <origin rpy="0 0 0" xyz="0 0 0.02"/>
      <material name="blue"/>
    </visual>
    <collision>
      <geometry>
        <cylinder length="0.04" radius="0.02"/>
      </geometry>
      <origin rpy="0 0 0" xyz="0 0 0.02"/>
    </collision>
  </link>
</robot>

